[2023-09-04 18:28:20,254] {taskinstance.py:1159} INFO - Dependencies all met for <TaskInstance: my_dag_id.A_get_users manual__2023-09-04T18:28:18.804957+00:00 [queued]>
[2023-09-04 18:28:20,267] {taskinstance.py:1159} INFO - Dependencies all met for <TaskInstance: my_dag_id.A_get_users manual__2023-09-04T18:28:18.804957+00:00 [queued]>
[2023-09-04 18:28:20,269] {taskinstance.py:1356} INFO - 
--------------------------------------------------------------------------------
[2023-09-04 18:28:20,269] {taskinstance.py:1357} INFO - Starting attempt 1 of 1
[2023-09-04 18:28:20,270] {taskinstance.py:1358} INFO - 
--------------------------------------------------------------------------------
[2023-09-04 18:28:20,289] {taskinstance.py:1377} INFO - Executing <Task(BashOperator): A_get_users> on 2023-09-04 18:28:18.804957+00:00
[2023-09-04 18:28:20,294] {standard_task_runner.py:52} INFO - Started process 3535 to run task
[2023-09-04 18:28:20,299] {standard_task_runner.py:79} INFO - Running: ['***', 'tasks', 'run', 'my_dag_id', 'A_get_users', 'manual__2023-09-04T18:28:18.804957+00:00', '--job-id', '10', '--raw', '--subdir', 'DAGS_FOLDER/my_first_dag.py', '--cfg-path', '/tmp/tmphzf_4v82', '--error-file', '/tmp/tmpz6cf1wak']
[2023-09-04 18:28:20,300] {standard_task_runner.py:80} INFO - Job 10: Subtask A_get_users
[2023-09-04 18:28:20,373] {task_command.py:369} INFO - Running <TaskInstance: my_dag_id.A_get_users manual__2023-09-04T18:28:18.804957+00:00 [running]> on host 7423ecc7bbb9
[2023-09-04 18:28:20,469] {taskinstance.py:1571} INFO - Exporting the following env vars:
AIRFLOW_CTX_DAG_OWNER=your_name
AIRFLOW_CTX_DAG_ID=my_dag_id
AIRFLOW_CTX_TASK_ID=A_get_users
AIRFLOW_CTX_EXECUTION_DATE=2023-09-04T18:28:18.804957+00:00
AIRFLOW_CTX_TRY_NUMBER=1
AIRFLOW_CTX_DAG_RUN_ID=manual__2023-09-04T18:28:18.804957+00:00
[2023-09-04 18:28:20,472] {subprocess.py:62} INFO - Tmp dir root location: 
 /tmp
[2023-09-04 18:28:20,474] {subprocess.py:74} INFO - Running command: ['bash', '-c', '/opt/***/scripts/run_r.sh /opt/***/scripts/A_task.R ']
[2023-09-04 18:28:20,486] {subprocess.py:85} INFO - Output:
[2023-09-04 18:28:20,488] {subprocess.py:92} INFO - bash: line 1: /opt/***/scripts/run_r.sh: No such file or directory
[2023-09-04 18:28:20,490] {subprocess.py:96} INFO - Command exited with return code 127
[2023-09-04 18:28:20,507] {taskinstance.py:1889} ERROR - Task failed with exception
Traceback (most recent call last):
  File "/home/airflow/.local/lib/python3.7/site-packages/airflow/operators/bash.py", line 195, in execute
    f'Bash command failed. The command returned a non-zero exit code {result.exit_code}.'
airflow.exceptions.AirflowException: Bash command failed. The command returned a non-zero exit code 127.
[2023-09-04 18:28:20,513] {taskinstance.py:1400} INFO - Marking task as FAILED. dag_id=my_dag_id, task_id=A_get_users, execution_date=20230904T182818, start_date=20230904T182820, end_date=20230904T182820
[2023-09-04 18:28:20,549] {standard_task_runner.py:97} ERROR - Failed to execute job 10 for task A_get_users (Bash command failed. The command returned a non-zero exit code 127.; 3535)
[2023-09-04 18:28:20,598] {local_task_job.py:156} INFO - Task exited with return code 1
[2023-09-04 18:28:20,670] {local_task_job.py:273} INFO - 0 downstream tasks scheduled from follow-on schedule check
